Workbook

Sheet Data Dosen
A1: No | B1: Nama | C1: Prodi | D1: Jumlah Matkul | E1: Jumlah Kelas | F1: Jumlah Responden | G1: Nilai Kuesioner | H1: Jumlah Kehadiran | I1: Konten | J1: Jumlah Penelitian | K1: Jumlah Pengabdian | L1: P1 | M1: P2 | N1: P3 | O1: P4 | P1: P5 | Q1: K1 | R1: K2 | S1: K3 | T1: K4
A2: 1 | B2: ANDY YUNIARSO, SE, MM, MBA | C2: Akuntansi | U2: .
A3: 2 | B3: DEA ARME TIARA HARAHAP, M.Ak. | C3: Akuntansi | D3: 8 | E3: 10 | F3: 131 dari 312 | G3: 4.52 | H3: 16 | I3: 3.37 | J3: 1 | K3: 2 | U3: .
A4: 3 | B4: DANIA MEIDA ROSYIDAH, M.Ak | C4: Akuntansi | D4: 3 | E4: 7 | F4: 81 dari 211 | G4: 4.15 | H4: 16 | I4: 3.4 | J4: 1 | K4: 2 | U4: .
A5: 4 | B5: ELIN PAULINA, MM | C5: Akuntansi | D5: 2 | E5: 5 | F5: 55 dari 167 | G5: 4.14 | H5: 16 | I5: 4.93 | J5: 1 | K5: 1 | U5: .
A6: 5 | B6: HELIANI, SE., M.Ak | C6: Akuntansi | D6: 4 | E6: 9 | F6: 154 dari 296 | G6: 4.26 | H6: 16 | I6: 4.01 | J6: 1 | K6: 2 | U6: .
A7: 6 | B7: IRWAN HERMAWAN, SE., ME | C7: Akuntansi | U7: .
A8: 7 | B8: MEUTIA RIANY, S.E., M,Ak | C8: Akuntansi | D8: 4 | E8: 8 | F8: 123 dari 236 | G8: 4.43 | H8: 16 | I8: 3.96 | J8: 2 | K8: 3 | U8: .
A9: 8 | B9: NANAN SUNANDAR, S.E., M. Akt | C9: Akuntansi | U9: .
A10: 9 | B10: NUR HIDAYAH KUSUMANINGRUM FADHILAH, SE.,M.Ak | C10: Akuntansi | D10: 4 | E10: 6 | F10: 129 dari 184 | G10: 4.22 | H10: 16 | I10: 4.68 | J10: 1 | K10: 1 | U10: .
A11: 10 | B11: SITI SARAH SOBARIAH LESTARI, M.Stat | C11: Akuntansi | D11: 2 | E11: 5 | F11: 61 dari 146 | G11: 3.85 | U11: .
A12: 11 | B12: TAOFIK MUHAMMAD GUMELAR, M.Ak | C12: Akuntansi | D12: 2 | E12: 11 | F12: 180 dari 322 | G12: 4.22 | H12: 16 | I12: 4.39 | J12: 1 | K12: 1 | U12: .
A13: 12 | B13: NURUL RUSDIANSYAH, M.Ak.., S.Akun | C13: Akuntansi | D13: 3 | E13: 7 | F13: 105 dari 191 | G13: 4.25 | H13: 16 | I13: 4.67 | U13: .
A14: 13 | B14: MUHAMMAD ZULVAN DWI HATMOKO, M.Acc | C14: Akuntansi | D14: 1 | E14: 6 | F14: 99 dari 181 | G14: 3.91 | H14: 16 | I14: 4.23 | U14: .
A15: 14 | B15: WAHYU MULYADI, S.AB., M.Si | C15: Akuntansi | U15: .
A16: 15 | B16: KHAIRUL MUJAHIDI, S.E., M.AK | C16: Akuntansi | D16: 1 | E16: 6 | F16: 102 dari 182 | G16: 4.12 | H16: 16 | I16: 4.55 | J16: 1 | K16: 1 | U16: .
A17: 16 | B17: NUR ALIM BAHRI, S.Ak., M.Ak | C17: Akuntansi | U17: .
A18: 17 | B18: ADI NURPERMANA, M.Ak | C18: Akuntansi | U18: .
A19: 18 | B19: SHERLITA NUROSIDAH, AE., M.Sc., ME | C19: Akuntansi | U19: .
A20: 19 | B20: HERMAN RUSTANDI, S.Ak., M.Ak | C20: Akuntansi | D20: 3 | E20: 11 | F20: 157 dari 334 | G20: 4.29 | H20: 16 | I20: 4.94 | U20: .
A21: 20 | B21: ARNI MAHARANI, S. Ak., M.Ak | C21: Akuntansi | U21: .
A22: 21 | B22: TIA SETIAWAN, M.Ak | C22: Akuntansi | D22: 2 | E22: 4 | F22: 43 dari 104 | G22: 4.24 | H22: 16 | I22: 5
A23: 22 | B23: KIKI YULIA RAMADHANI, SE., M.Tr.E | C23: Akuntansi | D23: 2 | E23: 8 | F23: 111 dari 231 | G23: 4.10 | H23: 16 | I23: 4.94
A24: 23 | B24: HERNY NURHAYATI, SE., MM., M.Si | C24: Akuntansi | D24: 1 | E24: 4 | F24: 78 dari 136 | G24: 4.01 | H24: 16 | I24: 5
A25: 24 | B25: AGUS DARMAWAN, S.Sn, M.Sn | C25: Desain Komunikasi Visual | D25: 2 | E25: 9 | F25: 72 dari 229 | G25: 4.23 | H25: 16 | I25: 3.69 | J25: 1 | K25: 1 | U25: .
A26: 25 | B26: ASEP WAHYUDIN, M.Sn | C26: Desain Komunikasi Visual | D26: 3 | E26: 4 | F26: 54 dari 123 | G26: 4.24 | H26: 16 | I26: 4.7 | J26: 0 | K26: 1 | U26: .
A27: 26 | B27: GESNIDA YUNITA, S.Sn, M.Sn, | C27: Desain Komunikasi Visual | D27: 1 | E27: 4 | F27: 15 dari 91 | G27: 4.46 | H27: 16 | I27: 4.88 | J27: 2 | K27: 2 | U27: .
A28: 27 | B28: Dr HERWAN, S.Pd.I., M.M.Pd | C28: Desain Komunikasi Visual | D28: 3 | E28: 18 | F28: 375 dari 620 | G28: 3.99 | H28: 16 | I28: 4.26 | J28: 1 | K28: 2 | U28: .
A29: 28 | B29: ICUH KOMALA, M.Sn | C29: Desain Komunikasi Visual | D29: 3 | E29: 9 | F29: 107 dari 278 | G29: 4.25 | H29: 16 | I29: 4.4 | J29: 1 | K29: 3 | U29: .
A30: 29 | B30: MOCHAMMAD FICKY AULIA, S.Ds., M.Sn | C30: Desain Komunikasi Visual | D30: 2 | E30: 7 | F30: 77 dari 208 | G30: 4.02 | H30: 16 | I30: 4.5 | J30: 1 | K30: 1 | U30: .
A31: 30 | B31: RARAY ISTIANAH, M.Pd | C31: Desain Komunikasi Visual | D31: 1 | E31: 4 | F31: 42 dari 115 | G31: 4.12 | H31: 16 | I31: 4.5 | J31: 2 | K31: 2 | U31: .
A32: 31 | B32: TULUS REGA WAHYUNI E, S.Kom.I., M.Sn | C32: Desain Komunikasi Visual | D32: 3 | E32: 9 | F32: 115 dari 281 | G32: 4.15 | H32: 16 | I32: 2.84 | J32: 1 | K32: 1 | U32: .
A33: 32 | B33: RIFKY NUGRAHA,, S.Pd., M.Ds | C33: Desain Komunikasi Visual | D33: 2 | E33: 10 | F33: 62 dari 236 | G33: 4.26 | H33: 16 | I33: 4.95 | J33: 1 | K33: 1 | U33: .
A34: 33 | B34: IRVING GUSTAV SALIM, S.Pd., M.Ds | C34: Desain Komunikasi Visual | D34: 2 | E34: 9 | F34: 93 dari 256 | G34: 4.32 | H34: 15 | I34: 1.36 | J34: 2 | K34: 1 | U34: .
A35: 34 | B35: FIRMAN MUTAQIN, S.Ds., M.Ds | C35: Desain Komunikasi Visual | D35: 2 | E35: 6 | F35: 60 dari 164 | G35: 4.19 | H35: 16 | I35: 4.37 | J35: 2 | K35: 1 | U35: .
A36: 35 | B36: S.Ds IRNI RESMI APRIYANTI, S.Ds., M.Ds | C36: Desain Komunikasi Visual | D36: 2 | E36: 7 | F36: 40 dari 160 | G36: 4.03 | H36: 15 | I36: 5 | J36: 1 | K36: 1 | U36: .
A37: 36 | B37: Dr WATI SOLIHAT SUKMAWATI, M.Pd | C37: Desain Komunikasi Visual | D37: 2 | E37: 11 | F37: 132 dari 333 | G37: 4.07 | H37: 15.8 | I37: 3.44 | J37: 1 | K37: 1 | U37: .
A38: 37 | B38: SAMUEL RIHI HADI UTOMO, S.Ds., M.A. | C38: Desain Komunikasi Visual | U38: .
A39: 38 | B39: RIZKY NOVIASRI, M.Ds | C39: Desain Komunikasi Visual | D39: 1 | E39: 5 | F39: 12 dari 95 | G39: 4.32 | H39: 16 | I39: 5 | U39: .
A40: 39 | B40: ANITA APRILIANI RAHAYU, S.Ds., M.Ds. | C40: Desain Komunikasi Visual | D40: 1 | E40: 5 | F40: 56 dari 153 | G40: 4.11 | H40: 16 | I40: 4.54 | U40: .
...

Sheet Skor Bobot
A1: NO | B1: A | C1: B | D1: C | E1: D | F1: E | H1: 1 | I1: 2 | J1: 3 | K1: 4 | L1: 5 | M1: Skor
H2: =B2*$H$1 -> 0 | I2: =C2*$I$1 -> 0 | J2: =D2*$J$1 -> 0 | K2: =E2*$K$1 -> 0 | L2: =F2*$L$1 -> 0 | M2: =SUM(H2:L2) -> 0
H3: =B3*$H$1 -> 0 | I3: =C3*$I$1 -> 0 | J3: =D3*$J$1 -> 0 | K3: =E3*$K$1 -> 0 | L3: =F3*$L$1 -> 0 | M3: =SUM(H3:L3) -> 0
H4: =B4*$H$1 -> 0 | I4: =C4*$I$1 -> 0 | J4: =D4*$J$1 -> 0 | K4: =E4*$K$1 -> 0 | L4: =F4*$L$1 -> 0 | M4: =SUM(H4:L4) -> 0
H5: =B5*$H$1 -> 0 | I5: =C5*$I$1 -> 0 | J5: =D5*$J$1 -> 0 | K5: =E5*$K$1 -> 0 | L5: =F5*$L$1 -> 0 | M5: =SUM(H5:L5) -> 0
H6: =B6*$H$1 -> 0 | I6: =C6*$I$1 -> 0 | J6: =D6*$J$1 -> 0 | K6: =E6*$K$1 -> 0 | L6: =F6*$L$1 -> 0 | M6: =SUM(H6:L6) -> 0
H7: =B7*$H$1 -> 0 | I7: =C7*$I$1 -> 0 | J7: =D7*$J$1 -> 0 | K7: =E7*$K$1 -> 0 | L7: =F7*$L$1 -> 0 | M7: =SUM(H7:L7) -> 0
H8: =B8*$H$1 -> 0 | I8: =C8*$I$1 -> 0 | J8: =D8*$J$1 -> 0 | K8: =E8*$K$1 -> 0 | L8: =F8*$L$1 -> 0 | M8: =SUM(H8:L8) -> 0
H9: =B9*$H$1 -> 0 | I9: =C9*$I$1 -> 0 | J9: =D9*$J$1 -> 0 | K9: =E9*$K$1 -> 0 | L9: =F9*$L$1 -> 0 | M9: =SUM(H9:L9) -> 0
H10: =B10*$H$1 -> 0 | I10: =C10*$I$1 -> 0 | J10: =D10*$J$1 -> 0 | K10: =E10*$K$1 -> 0 | L10: =F10*$L$1 -> 0 | M10: =SUM(H10:L10) -> 0
H11: =B11*$H$1 -> 0 | I11: =C11*$I$1 -> 0 | J11: =D11*$J$1 -> 0 | K11: =E11*$K$1 -> 0 | L11: =F11*$L$1 -> 0 | M11: =SUM(H11:L11) -> 0
H12: =B12*$H$1 -> 0 | I12: =C12*$I$1 -> 0 | J12: =D12*$J$1 -> 0 | K12: =E12*$K$1 -> 0 | L12: =F12*$L$1 -> 0 | M12: =SUM(H12:L12) -> 0
H13: =B13*$H$1 -> 0 | I13: =C13*$I$1 -> 0 | J13: =D13*$J$1 -> 0 | K13: =E13*$K$1 -> 0 | L13: =F13*$L$1 -> 0 | M13: =SUM(H13:L13) -> 0
... H1000: =B1000*$H$1 -> 0 | I1000: =C1000*$I$1 -> 0 | J1000: =D1000*$J$1 -> 0 | K1000: =E1000*$K$1 -> 0 | L1000: =F1000*$L$1 -> 0 | M1000: =SUM(H1000:L1000) -> 0

Sheet Skor
A1: No | B1: Skor | D1: No | E1: Skor
A2: ='Skor Bobot'!$A$2:$A$1000 -> 0 | B2: ='Skor Bobot'!$M$2:$M$1000 -> 0
A3: ='Skor Bobot'!$A$2:$A$1000 -> 0 | B3: ='Skor Bobot'!$M$2:$M$1000 -> 0
A4: ='Skor Bobot'!$A$2:$A$1000 -> 0 | B4: ='Skor Bobot'!$M$2:$M$1000 -> 0
A5: ='Skor Bobot'!$A$2:$A$1000 -> 0 | B5: ='Skor Bobot'!$M$2:$M$1000 -> 0
A6: ='Skor Bobot'!$A$2:$A$1000 -> 0 | B6: ='Skor Bobot'!$M$2:$M$1000 -> 0
A7: ='Skor Bobot'!$A$2:$A$1000 -> 0 | B7: ='Skor Bobot'!$M$2:$M$1000 -> 0
A8: ='Skor Bobot'!$A$2:$A$1000 -> 0 | B8: ='Skor Bobot'!$M$2:$M$1000 -> 0
A9: ='Skor Bobot'!$A$2:$A$1000 -> 0 | B9: ='Skor Bobot'!$M$2:$M$1000 -> 0
A10: ='Skor Bobot'!$A$2:$A$1000 -> 0 | B10: ='Skor Bobot'!$M$2:$M$1000 -> 0
A11: ='Skor Bobot'!$A$2:$A$1000 -> 0 | B11: ='Skor Bobot'!$M$2:$M$1000 -> 0
A12: ='Skor Bobot'!$A$2:$A$1000 -> 0 | B12: ='Skor Bobot'!$M$2:$M$1000 -> 0
A13: ='Skor Bobot'!$A$2:$A$1000 -> 0 | B13: ='Skor Bobot'!$M$2:$M$1000 -> 0
... A365: ='Skor Bobot'!$A$2:$A$1000 -> 0 | B365: ='Skor Bobot'!$M$2:$M$1000 -> 0

Sheet Rata-Rata
A1: Dummy | B1: No | C1: Kriteria | D1: No | F1: No | G1: Rata-Rata | I1: No | J1: Rata-Rata | L1: Obs | M1: No
D2: 1 | F2: 1 | G2: =AVERAGE(E2:E14) -> #DIV/0! | L2: 1 | M2: =SMALL($I$2:$I$11,L2) -> #NUM! | N2: =VLOOKUP(M2,$T$2:$U$29,2,FALSE) -> #NUM! | T2: 1 | U2: Kesiapan memberikan kuliah dan/atau praktek/praktikum
D3: 1 | F3: 2 | G3: =AVERAGE(E16:E28) -> #DIV/0! | L3: 2 | M3: =SMALL($I$2:$I$11,L3) -> #NUM! | N3: =VLOOKUP(M3,$T$2:$U$29,2,FALSE) -> #NUM! | T3: 2 | U3: Keteraturan dan ketertiban penyelengaraan perkuliahan
D4: 1 | F4: 3 | G4: =AVERAGE(E30:E42) -> #DIV/0! | L4: 3 | M4: =SMALL($I$2:$I$11,L4) -> #NUM! | N4: =VLOOKUP(M4,$T$2:$U$29,2,FALSE) -> #NUM! | T4: 3 | U4: Kemampuan menghidupkan suasana kelas
D5: 1 | F5: 4 | G5: =AVERAGE(E44:E56) -> #DIV/0! | L5: 4 | M5: =SMALL($I$2:$I$11,L5) -> #NUM! | N5: =VLOOKUP(M5,$T$2:$U$29,2,FALSE) -> #NUM! | T5: 4 | U5: Kejelasan penyampaian materi dan jawaban terhadap pertanyaan di kelas
D6: 1 | F6: 5 | G6: =AVERAGE(E58:E70) -> #DIV/0! | L6: 5 | M6: =SMALL($I$2:$I$11,L6) -> #NUM! | N6: =VLOOKUP(M6,$T$2:$U$29,2,FALSE) -> #NUM! | T6: 5 | U6: Pemanfaatan media dan teknologi pembelajaran
D7: 1 | F7: 6 | G7: =AVERAGE(E72:E84) -> #DIV/0! | T7: 6 | U7: Keanekaragaman cara pengukuran hasil belajar
D8: 1 | F8: 7 | G8: =AVERAGE(E86:E98) -> #DIV/0! | T8: 7 | U8: Pemberian umpan balik terhadap tugas
D9: 1 | F9: 8 | G9: =AVERAGE(E100:E112) -> #DIV/0! | T9: 8 | U9: Kesesuaian materi ujian dan/atau tugas dengan tujuan mata kuliah
D10: 1 | F10: 9 | G10: =AVERAGE(E114:E126) -> #DIV/0! | T10: 9 | U10: Kesesuaian nilai yang diberikan dengan hasil belajar
D11: 1 | F11: 10 | G11: =AVERAGE(E128:E140) -> #DIV/0! | T11: 10 | U11: Kemampuan menjelaskan pokok pembahasan/topik secara cepat
D12: 1 | F12: 11 | G12: =AVERAGE(E142:E154) -> #DIV/0! | T12: 11 | U12: Kemampuan memberikan contoh relevan dari konsep yang diajarkan
D13: 1 | F13: 12 | G13: =AVERAGE(E156:E168) -> #DIV/0! | T13: 12 | U13: Kemampuan menjelaskan keterkaitan bidang/topik yang di ajarkan dengan bidang/topik yang lain
D14: 1 | F14: 13 | G14: =AVERAGE(E170:E182) -> #DIV/0! | T14: 13 | U14: Kemampuan menjelaskan keterkaitan bidang/topik yang diajarkan dengan konteks
F15: 14 | G15: =AVERAGE(E184:E196) -> #DIV/0! | T15: 14 | U15: Penguasaan akan isu-isu mutakhir dalam bidang yang diajarkan
D16: 2 | F16: 15 | G16: =AVERAGE(E198:E210) -> #DIV/0! | T16: 15 | U16: Pengguanaan hasil-hasil penelitian untuk meningkatkan kualitas perkuliahaan
D17: 2 | F17: 16 | G17: =AVERAGE(E212:E224) -> #DIV/0! | T17: 16 | U17: Pelibatan mahasiswa dalam penelitian/kajian dan/atau pengembangan/rekayasa/desain yang dilakukan oleh dosen
D18: 2 | F18: 17 | G18: =AVERAGE(E226:E238) -> #DIV/0! | T18: 17 | U18: Kemampuan menggunakan beragam teknologi komunikasi
D19: 2 | F19: 18 | G19: =AVERAGE(E240:E252) -> #DIV/0! | T19: 18 | U19: Keawibawaan sebagai pribadi dosen
D20: 2 | F20: 19 | G20: =AVERAGE(E254:E266) -> #DIV/0! | T20: 19 | U20: Kearifan dalam mengambil keputusan
D21: 2 | F21: 20 | G21: =AVERAGE(E268:E280) -> #DIV/0! | T21: 20 | U21: Menjadi contoh dalam sikap dan perilaku
D22: 2 | F22: 21 | G22: =AVERAGE(E282:E366) -> #DIV/0! | T22: 21 | U22: Satunya kata dan tindakan
D23: 2 | F23: 22 | G23: =AVERAGE(E310:E381) -> #DIV/0! | T23: 22 | U23: Kemampuan mengendalikan diri dalam berbagai situasi dan kondisi
D24: 2 | F24: 23 | G24: =AVERAGE(E310:E322) -> #DIV/0! | T24: 23 | U24: Adil dalam memperlakukan mahasiswa
D25: 2 | F25: 24 | G25: =AVERAGE(E324:E336) -> #DIV/0! | T25: 24 | U25: Kemampuan menyampaikan pendapat
D26: 2 | F26: 25 | G26: =AVERAGE(E338:E350) -> #DIV/0! | T26: 25 | U26: Kemampuan menerima kritik, saran dan pendapat mahasiswa
D27: 2 | F27: 26 | G27: =AVERAGE(E352:E364) -> #DIV/0! | T27: 26 | U27: Mengenal dengan baik mahasiswa yang mengikuti kuliahnya
D28: 2 | F28: 27 | G28: =AVERAGE(E366:E378) -> #DIV/0! | T28: 27 | U28: Mudah bergaul di kalangan mahasiswa
F29: 28 | G29: =AVERAGE(E380:E392) -> #DIV/0! | T29: 28 | U29: Toleransi terhadap keberagaman mahasiswa
D30: 3
D31: 3
D32: 3
D33: 3
D34: 3
D35: 3
D36: 3
D37: 3
D38: 3
D39: 3
D40: 3
...

Sheet Rapot
M1: 1
A5: LAPORAN EVALUASI TRIDHARMA DOSEN
A6: GASAL 2025-2026
A7: NUSA PUTRA UNIVERSITY
A8: Jl. Raya Cibolang No. 21, Cibolang Kaler, Cisaat, Cibolang Kaler, Cisaat, Sukabumi, Jawa Barat 43152. Telp. (0266) 210594
A10: A. IDENTITAS DOSEN
B11: NAMA DOSEN | C11: =VLOOKUP($M$1,'Data Dosen'!$A$1:$K$1179,2,FALSE) -> ANDY YUNIARSO, SE, MM, MBA
B12: PROGRAM STUDI | C12: =VLOOKUP($M$1,'Data Dosen'!$A$1:$K$1179,3,FALSE) -> Akuntansi
B13: JUMLAH MATA KULIAH | C13: =VLOOKUP($M$1,'Data Dosen'!$A$1:$K$1179,4,FALSE) -> 0
B14: JUMLAH KELAS | C14: =VLOOKUP($M$1,'Data Dosen'!$A$1:$K$1179,5,FALSE) -> 0
B15: JUMLAH RESPONDEN | C15: =VLOOKUP($M$1,'Data Dosen'!$A$1:$K$1179,6,FALSE) -> 0
A16: B. REKAPITULASI PENILAIAN
B17: Indikator Penilaian | C17: Nilai | D17: Keterangan
B18: Kuesioner Mahasiswa | C18: =VLOOKUP($M$1,'Data Dosen'!$A$1:$K$1179,7,FALSE) -> 0 | D18: =IF(C18>=4.58,"Sangat Baik",IF(AND(C18>=4.12,C18<4.8),"Baik",IF(AND(C18>=3.66,C18<4.12),"Cukup","Kurang Baik"))) -> Kurang Baik
B19: Kehadiran | C19: =VLOOKUP($M$1,'Data Dosen'!$A$1:$K$1179,8,FALSE) -> 0 | D19: =IF(C19<14,"Belum Memenuhi","Sudah Memenuhi") -> Belum Memenuhi
B20: Kelengkapan Konten Perkuliahan | C20: =VLOOKUP($M$1,'Data Dosen'!$A$1:$K$1179,9,FALSE) -> 0 | D20: =IF(C20>=4.58,"Sangat Baik",IF(AND(C20>=4.12,C20<4.57),"Baik",IF(AND(C20>=3.66,C20<4.12),"Cukup","Kurang "))) -> Kurang
B21: Penelitian | C21: =VLOOKUP($M$1,'Data Dosen'!$A$1:$K$1179,10,FALSE) -> 0 | D21: =IF(C21>=1,"Memenuhi","Belum Memenuhi") -> Belum Memenuhi
B22: Pengabdian | C22: =VLOOKUP($M$1,'Data Dosen'!$A$1:$K$1179,11,FALSE) -> 0 | D22: =IF(C22>=1,"Memenuhi","Belum Memenuhi") -> Belum Memenuhi
A24: C. ASPEK PEMBELAJARAN
A25: C1. REKOMENDASI PERBAIKAN
A26: 1 | B26: =VLOOKUP($M$1,'Data Dosen'!$A$1:$T$1199,12,FALSE) -> 0
A27: 2 | B27: =VLOOKUP($M$1,'Data Dosen'!$A$1:$T$1199,13,FALSE) -> 0
A28: 3 | B28: =VLOOKUP($M$1,'Data Dosen'!$A$1:$T$1199,14,FALSE) -> 0
A29: 4 | B29: =VLOOKUP($M$1,'Data Dosen'!$A$1:$T$1199,15,FALSE) -> 0
A30: 5 | B30: =VLOOKUP($M$1,'Data Dosen'!$A$1:$T$1199,16,FALSE) -> 0
A32: D. CATATAN
A33: - | B33: =VLOOKUP($M$1,'Data Dosen'!$A$1:$T$1199,17,FALSE) -> 0
A34: - | B34: =VLOOKUP($M$1,'Data Dosen'!$A$1:$T$1199,18,FALSE) -> 0
A35: - | B35: =VLOOKUP($M$1,'Data Dosen'!$A$1:$T$1199,19,FALSE) -> 0
A36: - | B36: =VLOOKUP($M$1,'Data Dosen'!$A$1:$T$1199,20,FALSE) -> 0
B39: UNIT PENJAMINAN MUTU
B40: UNIVERSITAS NUSA PUTRA | C40: CATATAN: KRITERIA PENSKORAN
C41: RENTANG SKOR | E41: KRITERIA
C42: 3.2 | D42: s/d 3.65 | E42: Kurang Baik
C43: 3.66 | D43: s/d 4.11 | E43: Cukup
C44: 4.12 | D44: s/d 4.57 | E44: Baik
C45: 4.58 | D45: s/d 5.00 | E45: Sangat Baik
B46: Dr. SAMSUL PAHMI, M.Pd.
